<mujoco model="spatial_parallelogram_dual_finger">
  <compiler angle="degree" coordinate="local" eulerseq="xyz" inertiafromgeom="true"/>
  
  <option timestep="0.001" gravity="0 0 -9.81" iterations="50" tolerance="1e-10"/>

  <visual>
    <headlight diffuse="0.4 0.4 0.4" ambient="0.2 0.2 0.2" specular="0.1 0.1 0.1"/>
    <rgba haze="0.15 0.25 0.35 1"/>
    <global azimuth="120" elevation="-20"/>
  </visual>

  <default>
    <!-- 默认碰撞关闭 (0), 需要碰撞的物体显式开启 (1) -->
    <geom type="box" rgba="0.7 0.7 0.7 0.6" contype="0" conaffinity="0"/>
    <joint damping="0.05" armature="0.01" frictionloss="0.01"/>
    <default class="viz_axis">
        <geom type="box" size="0.0008 0.0002 0.0002" contype="0" conaffinity="0" rgba="1 1 1 0.1"/>
    </default>
    <default class="global_axis">
        <geom type="cylinder" size="0.002" contype="0" conaffinity="0"/>
    </default>
    <!-- 专门为碰撞体定义的类 -->
    <default class="collision_primitive">
        <geom contype="1" conaffinity="1"/>
    </default>
  </default>

  <asset>
    <texture type="skybox" builtin="gradient" rgb1="0.3 0.5 0.7" rgb2="0 0 0" width="512" height="3072"/>
    <texture type="2d" name="groundplane" builtin="checker" rgb1="0.2 0.3 0.4" rgb2="0.1 0.2 0.3" width="100" height="100"/>
    <material name="groundplane" texture="groundplane" texrepeat="10 10"/>
  </asset>

  <worldbody>
  
    <camera name="closeup" pos="0.15 -0.2 0.15" xyaxes="0.866 0.5 0 -0.3 0.5 0.8" mode="trackcom"/>
    
    <!-- 地板需开启碰撞，防止物体掉落 (虽然物体没有Z轴自由度，但为了物理正确性建议开启) -->
    <geom name="floor" size="0 0 .05" type="plane" material="groundplane" condim="3" contype="1" conaffinity="1"/>
    <light pos="0 0 3" dir="0 0 -1" directional="true" castshadow="true" diffuse="0.8 0.8 0.8" specular="0.3 0.3 0.3"/>

    <body name="world_axis" pos="0 0 0">
        <geom class="global_axis" fromto="0 0 0  0.025 0 0" rgba="1 0 0 1"/> 
        <geom class="global_axis" fromto="0 0 0  0 0.025 0" rgba="0 1 0 1"/> 
        <geom class="global_axis" fromto="0 0 0  0 0 0.025" rgba="0 0 1 1"/> 
    </body>

    <!-- ==================== 操作物体 (Object) ==================== -->

    <body name="object" pos="0 0 0.108">
        <joint name="object_hinge_z" type="hinge" axis="0 0 1" damping="0.01"/>
        <geom name="object_geom" type="box" size="0.02   0.02 0.023" rgba="0.2 0.9 0.2 1" 
              mass="0.05" condim="3" contype="1" conaffinity="1"/>
        <site name="object_center" rgba="0 0 0 0"/>
    </body>



    <!-- ==================== 右指 (Right Finger) ==================== -->
    <body name="figer_right" pos="0 -0.08 0">

        <body name="Frame_O_right" pos="0 0 0">
            <geom class="viz_axis" pos="0.0017 0 0" size="0.0017 0.0002 0.0002" rgba="1 0 0 1"/> 
            <geom class="viz_axis" pos="0 0.0017 0" size="0.0002 0.0017 0.0002" rgba="0 1 0 1"/> 
            <geom class="viz_axis" pos="0 0 0.0017" size="0.0002 0.0002 0.0017" rgba="0 0 1 1"/> 
        </body>

        <!-- OA Chain Right -->
        <body name="Link_OA_Chain_right" pos="0 0 0" euler="116 0 0"> 
          <joint name="OA_active_x_right"  type="hinge" axis="1 0 0" range="0 140" damping="0.5"/>
          <joint name="OA_passive_z_right" type="hinge" axis="0 0 1" range="-60 60" damping="0.1"/>
          <joint name="OA_active_y_right"  type="hinge" axis="0 1 0" range="-16 16" damping="0.5"/>

          <geom name="geom_OA_right" fromto="0 0 0  0 0 -0.034" size="0.0005" rgba="0.8 0.2 0.2 1"/>
        
          <body name="Link_AC_right" pos="0 0 -0.034" euler="90 0 0">
            <body name="Frame_A_right" pos="0 0 0">
                <geom class="viz_axis" pos="0.0017 0 0" rgba="1 0 0 0.1"/>
                <geom class="viz_axis" pos="0 0.0017 0" size="0.0002 0.0017 0.0002" rgba="0 1 0 0.1"/>
                <geom class="viz_axis" pos="0 0 0.0017" size="0.0002 0.0002 0.0017" rgba="0 0 1 0.1"/>
            </body>

            <joint name="A_passive_x_right" type="hinge" axis="1 0 0" damping="0.1"/>
            <geom name="geom_AC_right" fromto="0 0 0  0 0 -0.085" size="0.0005" rgba="0.8 0.5 0.5 0.6"/>

            <site name="site_C_pivot_A_right" pos="0 0 -0.085" size="0.005" rgba="1 1 0 0"/>
            <site name="site_C_axis_A_right" pos="0.02 0 -0.085" size="0.003" rgba="1 0.5 0 0"/>

            <body name="Frame_C_from_A_right" pos="0 0 -0.085">
                <geom class="viz_axis" pos="0.0017 0 0" rgba="1 0 0 0.1"/>
                <geom class="viz_axis" pos="0 0.0017 0" size="0.0002 0.0017 0.0002" rgba="0 1 0 0.1"/>
                <geom class="viz_axis" pos="0 0 0.0017" size="0.0002 0.0002 0.0017" rgba="0 0 1 0.1"/>
            </body>
          </body>
        </body>

        <!-- OB Chain Right -->
        <body name="Link_OB_Chain_right" pos="0 0 0" euler="206 0 0">
          <joint name="OB_active_x_right"  type="hinge" axis="1 0 0" range="-90 50" damping="0.5"/>
          <joint name="OB_passive_z_right" type="hinge" axis="0 0 1" range="-180 180" damping="0.1"/>
          <joint name="OB_active_y_right"  type="hinge" axis="0 1 0" range="-16 16" damping="0.5"/>

          <geom name="geom_OB_right" fromto="0 0 0  0 0 -0.085" size="0.0005" rgba="0.2 0.8 0.2 1"/>
          
          <body name="Link_BCP_right" pos="0 0 -0.085" euler="-90 0 0">
            <body name="Frame_B_right" pos="0 0 0">
                <geom class="viz_axis" pos="0.0017 0 0" rgba="1 0 0 0.1"/>
                <geom class="viz_axis" pos="0 0.0017 0" size="0.0002 0.0017 0.0002" rgba="0 1 0 0.1"/>
                <geom class="viz_axis" pos="0 0 0.0017" size="0.0002 0.0002 0.0017" rgba="0 0 1 0.1"/>
            </body>

            <joint name="B_passive_x_right" type="hinge" axis="1 0 0" damping="0.1"/>
            <geom name="geom_BP_right" fromto="0 0 0  0 0 -0.054" size="0.0005" rgba="0.2 0.2 0.8 0.6" />
            <site name="site_C_pivot_B_right" pos="0 0 -0.034" size="0.005" rgba="1 1 0 0"/>
            <site name="site_C_axis_B_right" pos="0.02 0 -0.034" size="0.003" rgba="1 0.5 0 0"/>
            
            <body name="Frame_C_from_B_right" pos="0 0 -0.034">
                <geom class="viz_axis" pos="0.0017 0 0" rgba="1 0 0 0.1"/>
                <geom class="viz_axis" pos="0 0.0017 0" size="0.0002 0.0017 0.0002" rgba="0 1 0 0.1"/>
                <geom class="viz_axis" pos="0 0 0.0017" size="0.0002 0.0002 0.0017" rgba="0 0 1 0.1"/>
            </body>
            
            <body name="Frame_P_right" pos="0 0 -0.054">
                <geom class="viz_axis" pos="0.0017 0 0" rgba="1 0 0 0.1"/>
                <geom class="viz_axis" pos="0 0.0017 0" size="0.0002 0.0017 0.0002" rgba="0 1 0 0.1"/>
                <geom class="viz_axis" pos="0 0 0.0017" size="0.0002 0.0002 0.0017" rgba="0 0 1 0.1"/>
            </body>

            <!-- 
                 重要修改：
                 原为 site，现改为 geom type="sphere"，并开启 contype="1" conaffinity="1" 
                 以实现与物体的碰撞。
            -->
            <geom name="tip_geom_right" pos="0 0 -0.054" size="0.006" type="sphere" rgba="0 1 1 1" contype="1" conaffinity="1"/>
          
          </body>
        </body>
    </body>

    <!-- ==================== 左指 (Left Finger, Symmetric) ==================== -->
    <!-- 位置对称 (y=0.08)，并绕Z轴旋转180度以面对右指 -->
    <body name="figer_left" pos="0 0.08 0" euler="0 0 180">

        <body name="Frame_O_left" pos="0 0 0">
            <geom class="viz_axis" pos="0.0017 0 0" size="0.0017 0.0002 0.0002" rgba="1 0 0 1"/> 
            <geom class="viz_axis" pos="0 0.0017 0" size="0.0002 0.0017 0.0002" rgba="0 1 0 1"/> 
            <geom class="viz_axis" pos="0 0 0.0017" size="0.0002 0.0002 0.0017" rgba="0 0 1 1"/> 
        </body>

        <!-- OA Chain Left -->
        <body name="Link_OA_Chain_left" pos="0 0 0" euler="116 0 0"> 
          <joint name="OA_active_x_left"  type="hinge" axis="1 0 0" range="0 140" damping="0.5"/>
          <joint name="OA_passive_z_left" type="hinge" axis="0 0 1" range="-60 60" damping="0.1"/>
          <joint name="OA_active_y_left"  type="hinge" axis="0 1 0" range="-16 16" damping="0.5"/>

          <geom name="geom_OA_left" fromto="0 0 0  0 0 -0.034" size="0.0005" rgba="0.8 0.2 0.2 1"/>
        
          <body name="Link_AC_left" pos="0 0 -0.034" euler="90 0 0">
            <body name="Frame_A_left" pos="0 0 0">
                <geom class="viz_axis" pos="0.0017 0 0" rgba="1 0 0 0.1"/>
                <geom class="viz_axis" pos="0 0.0017 0" size="0.0002 0.0017 0.0002" rgba="0 1 0 0.1"/>
                <geom class="viz_axis" pos="0 0 0.0017" size="0.0002 0.0002 0.0017" rgba="0 0 1 0.1"/>
            </body>

            <joint name="A_passive_x_left" type="hinge" axis="1 0 0" damping="0.1"/>
            <geom name="geom_AC_left" fromto="0 0 0  0 0 -0.085" size="0.0005" rgba="0.8 0.5 0.5 0.6"/>

            <site name="site_C_pivot_A_left" pos="0 0 -0.085" size="0.005" rgba="1 1 0 0"/>
            <site name="site_C_axis_A_left" pos="0.02 0 -0.085" size="0.003" rgba="1 0.5 0 0"/>

            <body name="Frame_C_from_A_left" pos="0 0 -0.085">
                <geom class="viz_axis" pos="0.0017 0 0" rgba="1 0 0 0.1"/>
                <geom class="viz_axis" pos="0 0.0017 0" size="0.0002 0.0017 0.0002" rgba="0 1 0 0.1"/>
                <geom class="viz_axis" pos="0 0 0.0017" size="0.0002 0.0002 0.0017" rgba="0 0 1 0.1"/>
            </body>
          </body>
        </body>

        <!-- OB Chain Left -->
        <body name="Link_OB_Chain_left" pos="0 0 0" euler="206 0 0">
          <joint name="OB_active_x_left"  type="hinge" axis="1 0 0" range="-90 50" damping="0.5"/>
          <joint name="OB_passive_z_left" type="hinge" axis="0 0 1" range="-180 180" damping="0.1"/>
          <joint name="OB_active_y_left"  type="hinge" axis="0 1 0" range="-16 16" damping="0.5"/>

          <geom name="geom_OB_left" fromto="0 0 0  0 0 -0.085" size="0.0005" rgba="0.2 0.8 0.2 1"/>
          
          <body name="Link_BCP_left" pos="0 0 -0.085" euler="-90 0 0">
            <body name="Frame_B_left" pos="0 0 0">
                <geom class="viz_axis" pos="0.0017 0 0" rgba="1 0 0 0.1"/>
                <geom class="viz_axis" pos="0 0.0017 0" size="0.0002 0.0017 0.0002" rgba="0 1 0 0.1"/>
                <geom class="viz_axis" pos="0 0 0.0017" size="0.0002 0.0002 0.0017" rgba="0 0 1 0.1"/>
            </body>

            <joint name="B_passive_x_left" type="hinge" axis="1 0 0" damping="0.1"/>
            <geom name="geom_BP_left" fromto="0 0 0  0 0 -0.054" size="0.0005" rgba="0.2 0.2 0.8 0.6" />
            <site name="site_C_pivot_B_left" pos="0 0 -0.034" size="0.005" rgba="1 1 0 0"/>
            <site name="site_C_axis_B_left" pos="0.02 0 -0.034" size="0.003" rgba="1 0.5 0 0"/>
            
            <body name="Frame_C_from_B_left" pos="0 0 -0.034">
                <geom class="viz_axis" pos="0.0017 0 0" rgba="1 0 0 0.1"/>
                <geom class="viz_axis" pos="0 0.0017 0" size="0.0002 0.0017 0.0002" rgba="0 1 0 0.1"/>
                <geom class="viz_axis" pos="0 0 0.0017" size="0.0002 0.0002 0.0017" rgba="0 0 1 0.1"/>
            </body>
            
            <body name="Frame_P_left" pos="0 0 -0.054">
                <geom class="viz_axis" pos="0.0017 0 0" rgba="1 0 0 0.1"/>
                <geom class="viz_axis" pos="0 0.0017 0" size="0.0002 0.0017 0.0002" rgba="0 1 0 0.1"/>
                <geom class="viz_axis" pos="0 0 0.0017" size="0.0002 0.0002 0.0017" rgba="0 0 1 0.1"/>
            </body>

            <!-- 左指尖碰撞体 -->
            <geom name="tip_geom_left" pos="0 0 -0.054" size="0.006" type="sphere" rgba="0 1 1 1" contype="1" conaffinity="1"/>

          </body>
        </body>
    </body>
  </worldbody>


  <equality>
    <!-- 右指闭链约束 -->
    <connect name="C_pivot_right" site1="site_C_pivot_A_right" site2="site_C_pivot_B_right" solimp="0.9 0.95 0.001" solref="0.02 1"/>
    <connect name="C_axis_right"  site1="site_C_axis_A_right"  site2="site_C_axis_B_right"  solimp="0.9 0.95 0.001" solref="0.02 1"/>
    
    <!-- 左指闭链约束 -->
    <connect name="C_pivot_left" site1="site_C_pivot_A_left" site2="site_C_pivot_B_left" solimp="0.9 0.95 0.001" solref="0.02 1"/>
    <connect name="C_axis_left"  site1="site_C_axis_A_left"  site2="site_C_axis_B_left"  solimp="0.9 0.95 0.001" solref="0.02 1"/>
  </equality>



  <tendon>
    <!-- 右指关节耦合 -->
    <fixed name="limit_angle_diff_right" range="-1.15192 0.331613">  
      <joint joint="OB_active_x_right" coef="1"/>
      <joint joint="OA_active_x_right" coef="-1"/>
    </fixed>

    <!-- 左指关节耦合 -->
    <fixed name="limit_angle_diff_left" range="-1.15192 0.331613">  
      <joint joint="OB_active_x_left" coef="1"/>
      <joint joint="OA_active_x_left" coef="-1"/>
    </fixed>
  </tendon>


  <actuator>
    <!-- 右指驱动 -->
    <position name="act_OA_x_right" joint="OA_active_x_right" kp="10" kv="1" ctrlrange="0 2.44346"/>
    <position name="act_OA_y_right" joint="OA_active_y_right" kp="10" kv="1" ctrlrange="-0.28 0.28"/>

    <position name="act_OB_x_right" joint="OB_active_x_right" kp="10" kv="1" ctrlrange="-1.57 0.872665"/>
    <position name="act_OB_y_right" joint="OB_active_y_right" kp="10" kv="1" ctrlrange="-0.28 0.28"/>

    <!-- 左指驱动 -->
    <position name="act_OA_x_left" joint="OA_active_x_left" kp="10" kv="1" ctrlrange="0 2.44346"/>
    <position name="act_OA_y_left" joint="OA_active_y_left" kp="10" kv="1" ctrlrange="-0.28 0.28"/>

    <position name="act_OB_x_left" joint="OB_active_x_left" kp="10" kv="1" ctrlrange="-1.57 0.872665"/>
    <position name="act_OB_y_left" joint="OB_active_y_left" kp="10" kv="1" ctrlrange="-0.28 0.28"/>
  </actuator>

</mujoco>